2025-09-30 22:21:12 | INFO | will_ai_agent_assignment.agent.data_collection_agent | Starting financial data collection agent
2025-09-30 22:21:12 | INFO | will_ai_agent_assignment.agent.data_collection_agent | Executing task: alpha_vantage, symbol=AAPL
2025-09-30 22:21:12 | INFO | will_ai_agent_assignment.agent.data_collection_agent | Quality metrics for alpha_vantage:AAPL | records=100 quality_score=1.00
2025-09-30 22:21:12 | INFO | will_ai_agent_assignment.agent.data_collection_agent | Executing task: alpha_vantage, symbol=MSFT
2025-09-30 22:21:24 | INFO | will_ai_agent_assignment.agent.data_collection_agent | Quality metrics for alpha_vantage:MSFT | records=100 quality_score=1.00
2025-09-30 22:21:24 | INFO | will_ai_agent_assignment.agent.data_collection_agent | Executing task: fred, series=CPIAUCSL
2025-09-30 22:21:24 | ERROR | will_ai_agent_assignment.agent.data_collection_agent | Task fred:CPIAUCSL failed: FRED API key not found in environment
Traceback (most recent call last):
  File "/Users/will/DataAI/will_ai_agent_assignment/agent/data_collection_agent.py", line 53, in run
    result = self._execute_task(task, clients[task.source_name])
  File "/Users/will/DataAI/will_ai_agent_assignment/agent/data_collection_agent.py", line 91, in _execute_task
    return client.fetch_series(task.series_id)
           ~~~~~~~~~~~~~~~~~~~^^^^^^^^^^^^^^^^
  File "/Users/will/DataAI/will_ai_agent_assignment/agent/api_clients.py", line 176, in fetch_series
    raise RuntimeError("FRED API key not found in environment")
RuntimeError: FRED API key not found in environment
2025-09-30 22:21:24 | INFO | will_ai_agent_assignment.agent.data_collection_agent | Collection workflow complete
2025-09-30 22:23:02 | INFO | will_ai_agent_assignment.agent.data_collection_agent | Starting financial data collection agent
2025-09-30 22:23:02 | INFO | will_ai_agent_assignment.agent.data_collection_agent | Executing task: alpha_vantage, symbol=AAPL
2025-09-30 22:23:04 | INFO | will_ai_agent_assignment.agent.data_collection_agent | Quality metrics for alpha_vantage:AAPL | records=100 quality_score=1.00
2025-09-30 22:23:04 | INFO | will_ai_agent_assignment.agent.data_collection_agent | Executing task: alpha_vantage, symbol=MSFT
2025-09-30 22:23:14 | INFO | will_ai_agent_assignment.agent.data_collection_agent | Quality metrics for alpha_vantage:MSFT | records=100 quality_score=1.00
2025-09-30 22:23:14 | INFO | will_ai_agent_assignment.agent.data_collection_agent | Executing task: fred, series=CPIAUCSL
2025-09-30 22:23:14 | INFO | will_ai_agent_assignment.agent.data_collection_agent | Quality metrics for fred:CPIAUCSL | records=944 quality_score=0.66
2025-09-30 22:23:14 | INFO | will_ai_agent_assignment.agent.data_collection_agent | Collection workflow complete
2025-09-30 22:26:18 | INFO | will_ai_agent_assignment.agent.data_collection_agent | Starting financial data collection agent
2025-09-30 22:26:18 | INFO | will_ai_agent_assignment.agent.data_collection_agent | Executing task: alpha_vantage, symbol=AAPL
2025-09-30 22:26:18 | WARNING | will_ai_agent_assignment.agent.api_clients | Request error for alpha_vantage attempt 1/3: HTTPSConnectionPool(host='www.alphavantage.co', port=443): Max retries exceeded with url: /query?function=TIME_SERIES_DAILY&symbol=AAPL&apikey=CV16NWK5ASL7F1F5 (Caused by NewConnectionError('<urllib3.connection.HTTPSConnection object at 0x7f9a082e1220>: Failed to establish a new connection: [Errno 8] nodename nor servname provided, or not known')) (sleep 12.0s)
2025-09-30 22:26:30 | WARNING | will_ai_agent_assignment.agent.api_clients | Request error for alpha_vantage attempt 2/3: HTTPSConnectionPool(host='www.alphavantage.co', port=443): Max retries exceeded with url: /query?function=TIME_SERIES_DAILY&symbol=AAPL&apikey=CV16NWK5ASL7F1F5 (Caused by NewConnectionError('<urllib3.connection.HTTPSConnection object at 0x7f9a48271f70>: Failed to establish a new connection: [Errno 8] nodename nor servname provided, or not known')) (sleep 24.0s)
2025-09-30 22:26:54 | WARNING | will_ai_agent_assignment.agent.api_clients | Request error for alpha_vantage attempt 3/3: HTTPSConnectionPool(host='www.alphavantage.co', port=443): Max retries exceeded with url: /query?function=TIME_SERIES_DAILY&symbol=AAPL&apikey=CV16NWK5ASL7F1F5 (Caused by NewConnectionError('<urllib3.connection.HTTPSConnection object at 0x7f9a48271670>: Failed to establish a new connection: [Errno 8] nodename nor servname provided, or not known')) (sleep 48.0s)
2025-09-30 22:27:42 | ERROR | will_ai_agent_assignment.agent.data_collection_agent | Task alpha_vantage:AAPL failed: HTTPSConnectionPool(host='www.alphavantage.co', port=443): Max retries exceeded with url: /query?function=TIME_SERIES_DAILY&symbol=AAPL&apikey=CV16NWK5ASL7F1F5 (Caused by NewConnectionError('<urllib3.connection.HTTPSConnection object at 0x7f9a48271670>: Failed to establish a new connection: [Errno 8] nodename nor servname provided, or not known'))
Traceback (most recent call last):
  File "/Users/will/DataAI/will_ai_agent_assignment/agent/data_collection_agent.py", line 53, in run
    result = self._execute_task(task, clients[task.source_name])
  File "/Users/will/DataAI/will_ai_agent_assignment/agent/data_collection_agent.py", line 89, in _execute_task
    return client.fetch_daily_series(task.symbol, function=task.params.get("function"))
  File "/Users/will/DataAI/will_ai_agent_assignment/agent/api_clients.py", line 134, in fetch_daily_series
    payload, latency = self.get(params)
  File "/Users/will/DataAI/will_ai_agent_assignment/agent/api_clients.py", line 116, in get
    raise RuntimeError(last_error or "Unknown request failure")
RuntimeError: HTTPSConnectionPool(host='www.alphavantage.co', port=443): Max retries exceeded with url: /query?function=TIME_SERIES_DAILY&symbol=AAPL&apikey=CV16NWK5ASL7F1F5 (Caused by NewConnectionError('<urllib3.connection.HTTPSConnection object at 0x7f9a48271670>: Failed to establish a new connection: [Errno 8] nodename nor servname provided, or not known'))
2025-09-30 22:27:42 | INFO | will_ai_agent_assignment.agent.data_collection_agent | Executing task: alpha_vantage, symbol=MSFT
2025-09-30 22:27:42 | WARNING | will_ai_agent_assignment.agent.api_clients | Request error for alpha_vantage attempt 1/3: HTTPSConnectionPool(host='www.alphavantage.co', port=443): Max retries exceeded with url: /query?function=TIME_SERIES_DAILY&symbol=MSFT&apikey=CV16NWK5ASL7F1F5 (Caused by NewConnectionError('<urllib3.connection.HTTPSConnection object at 0x7f9a082e12e0>: Failed to establish a new connection: [Errno 8] nodename nor servname provided, or not known')) (sleep 12.0s)
2025-09-30 22:27:54 | WARNING | will_ai_agent_assignment.agent.api_clients | Request error for alpha_vantage attempt 2/3: HTTPSConnectionPool(host='www.alphavantage.co', port=443): Max retries exceeded with url: /query?function=TIME_SERIES_DAILY&symbol=MSFT&apikey=CV16NWK5ASL7F1F5 (Caused by NewConnectionError('<urllib3.connection.HTTPSConnection object at 0x7f9a082e1970>: Failed to establish a new connection: [Errno 8] nodename nor servname provided, or not known')) (sleep 24.0s)
2025-09-30 22:28:18 | WARNING | will_ai_agent_assignment.agent.api_clients | Request error for alpha_vantage attempt 3/3: HTTPSConnectionPool(host='www.alphavantage.co', port=443): Max retries exceeded with url: /query?function=TIME_SERIES_DAILY&symbol=MSFT&apikey=CV16NWK5ASL7F1F5 (Caused by NewConnectionError('<urllib3.connection.HTTPSConnection object at 0x7f9a082e12b0>: Failed to establish a new connection: [Errno 8] nodename nor servname provided, or not known')) (sleep 48.0s)
2025-09-30 22:29:06 | ERROR | will_ai_agent_assignment.agent.data_collection_agent | Task alpha_vantage:MSFT failed: HTTPSConnectionPool(host='www.alphavantage.co', port=443): Max retries exceeded with url: /query?function=TIME_SERIES_DAILY&symbol=MSFT&apikey=CV16NWK5ASL7F1F5 (Caused by NewConnectionError('<urllib3.connection.HTTPSConnection object at 0x7f9a082e12b0>: Failed to establish a new connection: [Errno 8] nodename nor servname provided, or not known'))
Traceback (most recent call last):
  File "/Users/will/DataAI/will_ai_agent_assignment/agent/data_collection_agent.py", line 53, in run
    result = self._execute_task(task, clients[task.source_name])
  File "/Users/will/DataAI/will_ai_agent_assignment/agent/data_collection_agent.py", line 89, in _execute_task
    return client.fetch_daily_series(task.symbol, function=task.params.get("function"))
  File "/Users/will/DataAI/will_ai_agent_assignment/agent/api_clients.py", line 134, in fetch_daily_series
    payload, latency = self.get(params)
  File "/Users/will/DataAI/will_ai_agent_assignment/agent/api_clients.py", line 116, in get
    raise RuntimeError(last_error or "Unknown request failure")
RuntimeError: HTTPSConnectionPool(host='www.alphavantage.co', port=443): Max retries exceeded with url: /query?function=TIME_SERIES_DAILY&symbol=MSFT&apikey=CV16NWK5ASL7F1F5 (Caused by NewConnectionError('<urllib3.connection.HTTPSConnection object at 0x7f9a082e12b0>: Failed to establish a new connection: [Errno 8] nodename nor servname provided, or not known'))
2025-09-30 22:29:06 | INFO | will_ai_agent_assignment.agent.data_collection_agent | Executing task: fred, series=CPIAUCSL
2025-09-30 22:29:06 | WARNING | will_ai_agent_assignment.agent.api_clients | Request error for fred attempt 1/3: HTTPSConnectionPool(host='api.stlouisfed.org', port=443): Max retries exceeded with url: /fred/series/observations?series_id=CPIAUCSL&api_key=0fb0b96dbec5f1628bc0c9cfbe0e04c7&file_type=json (Caused by NewConnectionError('<urllib3.connection.HTTPSConnection object at 0x7f9a082e1ca0>: Failed to establish a new connection: [Errno 8] nodename nor servname provided, or not known')) (sleep 12.0s)
2025-09-30 22:29:18 | WARNING | will_ai_agent_assignment.agent.api_clients | Request error for fred attempt 2/3: HTTPSConnectionPool(host='api.stlouisfed.org', port=443): Max retries exceeded with url: /fred/series/observations?series_id=CPIAUCSL&api_key=0fb0b96dbec5f1628bc0c9cfbe0e04c7&file_type=json (Caused by NewConnectionError('<urllib3.connection.HTTPSConnection object at 0x7f9a082e1cd0>: Failed to establish a new connection: [Errno 8] nodename nor servname provided, or not known')) (sleep 24.0s)
2025-09-30 22:29:42 | WARNING | will_ai_agent_assignment.agent.api_clients | Request error for fred attempt 3/3: HTTPSConnectionPool(host='api.stlouisfed.org', port=443): Max retries exceeded with url: /fred/series/observations?series_id=CPIAUCSL&api_key=0fb0b96dbec5f1628bc0c9cfbe0e04c7&file_type=json (Caused by NewConnectionError('<urllib3.connection.HTTPSConnection object at 0x7f9a082e1c70>: Failed to establish a new connection: [Errno 8] nodename nor servname provided, or not known')) (sleep 48.0s)
2025-09-30 22:30:30 | ERROR | will_ai_agent_assignment.agent.data_collection_agent | Task fred:CPIAUCSL failed: HTTPSConnectionPool(host='api.stlouisfed.org', port=443): Max retries exceeded with url: /fred/series/observations?series_id=CPIAUCSL&api_key=0fb0b96dbec5f1628bc0c9cfbe0e04c7&file_type=json (Caused by NewConnectionError('<urllib3.connection.HTTPSConnection object at 0x7f9a082e1c70>: Failed to establish a new connection: [Errno 8] nodename nor servname provided, or not known'))
Traceback (most recent call last):
  File "/Users/will/DataAI/will_ai_agent_assignment/agent/data_collection_agent.py", line 53, in run
    result = self._execute_task(task, clients[task.source_name])
  File "/Users/will/DataAI/will_ai_agent_assignment/agent/data_collection_agent.py", line 91, in _execute_task
    return client.fetch_series(task.series_id)
  File "/Users/will/DataAI/will_ai_agent_assignment/agent/api_clients.py", line 185, in fetch_series
    payload, latency = self.get(params)
  File "/Users/will/DataAI/will_ai_agent_assignment/agent/api_clients.py", line 116, in get
    raise RuntimeError(last_error or "Unknown request failure")
RuntimeError: HTTPSConnectionPool(host='api.stlouisfed.org', port=443): Max retries exceeded with url: /fred/series/observations?series_id=CPIAUCSL&api_key=0fb0b96dbec5f1628bc0c9cfbe0e04c7&file_type=json (Caused by NewConnectionError('<urllib3.connection.HTTPSConnection object at 0x7f9a082e1c70>: Failed to establish a new connection: [Errno 8] nodename nor servname provided, or not known'))
2025-09-30 22:30:30 | ERROR | will_ai_agent_assignment.agent.data_collection_agent | No datasets collected; aborting report generation
